Workbook
Name _Fill: #REF!
Name _Fill: #REF!
Name _Fill: #REF!
Name _Key1: #REF!
Name _Key1: #REF!
Name _Key1: #REF!
Name _Key2: #REF!
Name _Key2: #REF!
Name _Key2: #REF!
Name _Order1: 255
Name _Order2: 255
Name _Sort: #REF!
Name _Sort: #REF!
Name _Sort: #REF!
Name A: #REF!
Name A: #REF!
Name A.18: #REF!
Name A.18: #REF!
Name A.18_74: '[1]DAFTAR ANALYSA'!#REF!
Name A.18_74: '[1]DAFTAR ANALYSA'!#REF!
Name A.18_76: #REF!
Name A.18_76: #REF!
Name A.18_76_86: '[2]TEMBUS TPI ok Dokumen'!#REF!
Name A.18_76_86: '[2]TEMBUS TPI ok Dokumen'!#REF!
Name A.18_77: #REF!
Name A.18_77: #REF!
Name A.18_78: #REF!
Name A.18_78: #REF!
Name A.18_78_89: '[2]BJNGBTAT_PADURKSA ok _2_'!#REF!
Name A.18_78_89: '[2]BJNGBTAT_PADURKSA ok _2_'!#REF!
Name A.18_79: #REF!
Name A.18_79: #REF!
Name A.18_79_122: '[2]SULAWESI _2_'!#REF!
Name A.18_79_122: '[2]SULAWESI _2_'!#REF!
Name A.18_79_91: '[2]MENUR ok Dokumen'!#REF!
Name A.18_79_91: '[2]MENUR ok Dokumen'!#REF!
Name A.18_79_92: [2]SULAWESI!#REF!
Name A.18_79_92: [2]SULAWESI!#REF!
Name A.18_79_93: '[2]SULAWESI Dokumen'!#REF!
Name A.18_79_93: '[2]SULAWESI Dokumen'!#REF!
Name A.18_80: #REF!
Name A.18_80: #REF!
Name A.18_81: #REF!
Name A.18_81: #REF!
Name A.18_81_96: '[2]KOTA COMAL _Dokumen_'!#REF!
Name A.18_81_96: '[2]KOTA COMAL _Dokumen_'!#REF!
Name A.18_82: #REF!
Name A.18_82: #REF!
Name A.18_82_98: '[2]LING KOTA COMAL _Dokumen_'!#REF!
Name A.18_82_98: '[2]LING KOTA COMAL _Dokumen_'!#REF!
Name A.18_83: #REF!
Name A.18_83: #REF!
Name A.18_83_100: '[2]TERMINAL COMAL _Dokumen_'!#REF!
Name A.18_83_100: '[2]TERMINAL COMAL _Dokumen_'!#REF!
Name A.18_84: #REF!
Name A.18_84: #REF!
Name A.18_84_102: '[2]AMBOKULON_BLENDUNG _Dokumen_'!#REF!
Name A.18_84_102: '[2]AMBOKULON_BLENDUNG _Dokumen_'!#REF!
Name A.18_85: #REF!
Name A.18_85: #REF!

Sheet ISIAN DATA
A2: No : 400.12.3.1/003/VII/2026
B6: Nama Kepala Keluarga | E6: BUDIANTO
B7: Nomor Kartu Keluarga | E7: 3327042311210005
B9: BAYI/ANAK
B11: 1. | C11: Nama | E11: KHALIFA SYAKILA RAMADHANI
B12: 2. | C12: Jenis Kelamin | E12: 2
B13: 3. | C13: Tempat dilahirkan
B14: 4. | C14: Tempat Kelahiran | E14: PEMALANG
B15: 5. | C15: Hari dan Tanggal lahir | F15: TGL | G15: BLN | H15: THN | I15: UMUR
B16: 6. | C16: Pukul | E16: 0900 | F16: 03 | G16: 04 | H16: 2022 | I16: =IF(H16="","", YEAR(TODAY())-H16) -> 4
B17: 7. | C17: Jenis Kelahiran/ TANGGAL | I17: =IF(H17="","", YEAR(TODAY())-H17)
B18: 8. | C18: Kelahiran Ke | E18: 1 | I18: =IF(H18="","", YEAR(TODAY())-H18)
B19: 9. | C19: Penolong Kelahiran | I19: =IF(H19="","", YEAR(TODAY())-H19)
B20: 10. | C20: Berat Bayi | E20: 3000 | I20: =IF(H20="","", YEAR(TODAY())-H20)
B21: 11. | C21: Panjang Bayi | E21: 48 | I21: =IF(H21="","", YEAR(TODAY())-H21)
I22: =IF(H22="","", YEAR(TODAY())-H22)
B23: IBU | I23: =IF(H23="","", YEAR(TODAY())-H23)
B24: 1. | C24: NIK | E24: 3327047103960002 | I24: =IF(H24="","", YEAR(TODAY())-H24)
B25: 2. | C25: Nama Lengkap | E25: KHAFSOH | F25: TGL | G25: BLN | H25: THN | I25: UMUR
B26: 3. | C26: Tanggal lahir/Umur | F26: 31 | G26: 03 | H26: 1996 | I26: =IF(H26="","", YEAR(TODAY())-H26) -> 30
B27: 4. | C27: Pekerjaan | E27: 01 | I27: =IF(H27="","", YEAR(TODAY())-H27)
B28: 5. | C28: Alamat | E28: RT 004 / 004 DESA TAMBI | I28: =IF(H28="","", YEAR(TODAY())-H28)
I29: =IF(H29="","", YEAR(TODAY())-H29)
I30: =IF(H30="","", YEAR(TODAY())-H30)
B31: 6. | C31: Kewarganegaraan | I31: =IF(H31="","", YEAR(TODAY())-H31)
B32: 7. | C32: Kebangsaan | E32: INDONESIA | I32: =IF(H32="","", YEAR(TODAY())-H32)
B33: 8. | C33: Tgl.Pencatatan Perkawinan | F33: TGL | G33: BLN | H33: THN | I33: UMUR
F34: 10 | G34: 08 | H34: 2020 | I34: =IF(H34="","", YEAR(TODAY())-H34) -> 6
B35: AYAH | I35: =IF(H35="","", YEAR(TODAY())-H35)
B36: 1. | C36: NIK | E36: 3327042511940003 | I36: =IF(H36="","", YEAR(TODAY())-H36)
B37: 2. | C37: Nama Lengkap | E37: BUDIANTO | I37: =IF(H37="","", YEAR(TODAY())-H37)
B38: 3. | C38: Tanggal lahir/Umur | F38: TGL | G38: BLN | H38: THN | I38: UMUR
B39: 4. | C39: Pekerjaan | E39: 09 | F39: 25 | G39: 11 | H39: 1994 | I39: =IF(H39="","", YEAR(TODAY())-H39) -> 32
B40: 5. | C40: Alamat | E40: RT 004 / 004 DESA TAMBI | I40: =IF(H40="","", YEAR(TODAY())-H40)
B43: 6. | C43: Kewarganegaraan
B44: 7. | C44: Kebangsaan | E44: INDONESIA
B46: PELAPOR
B47: 1. | C47: NIK | E47: 3327042511940003
B48: 2. | C48: Nama Lengkap | E48: BUDIANTO
B49: 3. | C49: Umur | E49: 32
...

Sheet kwiTANSI
A1: Program Percepatan Pembanguan Desa | K1: Form. 5.a
A4: PROGRAM PERCEPATAN PEMBANGUNAN DESA
A5: TAHUN ANGGARAN 2013
A7: KUITANSI
A10: Telah terima dari | C10: : | D10: Ketua Kelompok Masyarakat Swakelola Desa Tambi
D11: Kecamatan Watukumpul, Kabuapaten Pemalang
A13: Uang sebesar | C13: : | D13: Rp. | E13: 150000
A16: Terbilang | C16: : | D16: Seratus limapuluh ribu rupiah.
A19: Untuk keperluan | C19: : | D19: Pembayaran Papan Nama Proyek
D23: Lokasi = Desa atambi
D24: No DO = ……………………….
D25: Volume = 1 Unit.
D29: Dalam rangka pelaksanaan Program Percepatan Pembangunan Desa
D30: Desa Tambi Kecamatan Watukumpul
A32: Jenis Pekerjaan | C32: : | D32: Pengaspalan Jalan
J36: Tambi,29 Mei 2015
B37: Yang Membayar | I37: Yang Menerima
B38: Bendahara Pokmas
B42: JULI SANTOSO | I42: M.JEFRI
F44: Mengetahui
B45: Ketua Pokmas | I45: Checker
B50: SUNARYA | I50: RUSDI

Sheet PAPAN PROYEK
Q2: 100
H6: PEMERINTAH KABUPATEN PEMALANG
H7: KECAMATAN …………………..
H8: DESA …………………..
H9: PROGRAM PERCEPATAN PEMBANGUNAN DESA TAHUN 2013
F11: JENIS PEKERJAAN | O11: : | P11: PERKERASAN TELFORD : 1.734 X 2.5 M
F12: SUB PEKERJAAN | O12: : | P12: REHAB JEMBATAN BETON : 4 X 6 M (1 UNIT)
O13: : | P13: GORONG-GORONG PLAT : 1 X 6 M (1 UNIT)
O14: : | P14: TALUD JALAN : 168 M
F15: LOKASI | O15: : | P15: DUSUN……….RT…../RW…………
F16: ALOKASI DANA APBD | O16: : | P16: BELANJA KONSTRUKSI | Z16: Rp. | AB16: ='[13]RekapRAB '!Q24 -> 259102000 | AJ16: 80
P17: OP. Perencanaan | Z17: Rp. | AB17: =AB16*1/100 -> 2591020
P18: OP. Pelaksnaaan | Z18: Rp. | AB18: =AB17*2 -> 5182040
P19: OP. Pengawasan | Z19: Rp. | AB19: =AB17 -> 2591020
F20: SWADAYA MASYARAKAT | O20: : | Z20: Rp. | AB20: ='[13]RekapRAB '!R24 -> 12000000
P21: TOTAL BIAYA | Z21: Rp. | AB21: =SUM(AB16:AB20) -> 281466080
F22: PELAKSANA | O22: : | P22: KELOMPOK MASYARAKAT SWAKELOLA
F23: WAKTU PELAKSANAAN | O23: : | P23: APRIL- AGUSTUS 2013 ( 150 HARI KALENDER )
P26: PAPAN PROYEK | AM26: KETENTUAN PAPAN KEGIATAN
AM27: 1. Papan media terbuat dari papan dengan ukuran jadi 80x100 cm
AM28: 2. Papan media diberi rangka kayu reng 2/3
AM29: 3. Bahan MMT cetak
AM30: 4. Warna dasar papan media dan tiang putih, tulisan warna hitam.
E31: 300 | AM31: 5. Tiang ukuran 5/7-300 cm (termasuk yang di tanam).

Sheet form 3 RPD
A1: Program Percepatan Pembanguan Desa
A3: RENCANA PENGGUNAAN DANA
D4: Tahap ….. ( …... %)
A5: Desa :
A6: Kecamatan :
A7: Kabupaten :
A8: No. | B8: Uraian | C8: Volume | H8: Harga
C9: Kebutuhan | D9: Realisasi s/d | E9: Pengajuan | F9: Jumlah | G9: Unit/ | H9: Satuan | I9: Jumlah
D10: tahap lalu | E10: sekarang | F10: Kumulatif | G10: Satuan | H10: Rp. | I10: Rp.
E36: Total Pengajuan | H36: Rp.
B37: ( ............................................................................................................................................)
G39: .........., | H39: ......201...
B40: Disetujui | G40: Dibuat oleh
B41: Kepala Desa | F41: Ketua Pokmas Desa .........
B45: ( ____________ ) | G45: ( _____________ )
D47: Mengetahui
B48: PPKom | G48: PPTK
B52: ( _________________ ) | G52: ( _____________ )
E54: Camat ……………
E57: ( )

Sheet Form.N-1
F2: Lampiran PMA:No.11 Tahun 2007 | P2: Lampiran PMA:No.11 Tahun 2007
G3: -Pasal 5 ayat (2) huruf a | Q3: -Pasal 5 ayat (2) huruf a
G4: Model N-1 | Q4: Model N-1
B6: KANTOR DESA/KELURAHAN | D6: : | E6: TAMBI | L6: KANTOR DESA/KELURAHAN | N6: : | O6: TAMBI
B7: KECAMATAN | D7: : | E7: WATUKUMPUL | L7: KECAMATAN | N7: : | O7: WATUKUMPUL
B8: KABUPATEN/KOTA | D8: : | E8: PEMALANG | L8: KABUPATEN/KOTA | N8: : | O8: PEMALANG
B11: SURAT KETERANGAN UNTUK NIKAH | L11: SURAT KETERANGAN UNTUK NIKAH
B12: Nomor:474.2/ 235 /XI / 2017 | L12: Nomor:474.2/ / / 2017
B14: Yang bertanda tangan dibawah ini menerangkan dengan sesungguhnya bahwa: | L14: Yang bertanda tangan dibawah ini menerangkan dengan sesungguhnya bahwa:
B16: 1. | C16: Nama lengkap dan alias | D16: : | E16: AMAR MA'RUF | L16: 1. | M16: Nama lengkap dan alias | N16: : | O16: ..............................................................
B17: 2. | C17: Jenis Kelamin | D17: : | E17: Laki-laki | L17: 2. | M17: Jenis Kelamin | N17: : | O17: ..............................................................
B18: 3. | C18: Tempat dan tanggal lahir | D18: : | E18: Pemalang,06 Mei 1988 | L18: 3. | M18: Tempat dan tanggal lahir | N18: : | O18: ..............................................................
B19: 4. | C19: Warganegara | D19: : | E19: Indonesia | L19: 4. | M19: Warganegara | N19: : | O19: Indonesia
B20: 5. | C20: Agama | D20: : | E20: Islam | L20: 5. | M20: Agama | N20: : | O20: Islam
B21: 6. | C21: Pekerjaan | D21: : | E21: Wiraswasta | L21: 6. | M21: Pekerjaan | N21: : | O21: ..............................................................
B22: 7. | C22: Tempat tinggal | D22: : | E22: Desa Tambi RT.006 RW.001 | L22: 7. | M22: Tempat tinggal | N22: : | O22: Desa Tambi RT.00 RW.00
B23: 8. | C23: Bin / Binti | D23: : | E23: TAMIARJA | L23: 8. | M23: Bin / Binti | N23: : | O23: ..............................................................
B24: 9. | C24: Status Perkawinan | D24: : | L24: 9. | M24: Status Perkawinan | N24: : | O24: ..............................................................
C25: a. Jika pria,terangkan jejaka, | M25: a. Jika pria,terangkan jejaka,
C26: duda atau beristri dan | M26: duda atau beristri dan
C27: berapa istrinya | D27: : | E27: JEJAKA | M27: berapa istrinya | N27: : | O27: ..............................................................
C29: b. Jika wanita terangkan | M29: b. Jika wanita terangkan
C30: perawan atau janda | D30: : | E30: .............................................................. | M30: perawan atau janda | N30: : | O30: ..............................................................
B32: 10. | C32: Nama Istri/Suami terdahulu | D32: : | E32: .............................................................. | L32: 10. | M32: Nama Istri/Suami terdahulu | N32: : | O32: ..............................................................
C34: Demikianlah,surat keterangan inii dibuat dengan mengingat sumpah jabatan dan | M34: Demikianlah,surat keterangan inii dibuat dengan mengingat sumpah jabatan dan
B35: untuk digunakan seperlunya. | L35: untuk digunakan seperlunya.
F37: Tambi,Nopember 2017 | P37: Tambi,...........................2017
F39: Kepala Desa/Lurah Tambi | P39: Kepala Desa/Lurah Tambi
F43: S O B I Y A H | P43: S O B I Y A H
P47: Lampiran PMA:No.11 Tahun 2007
Q48: -Pasal 5 ayat (2) huruf a
Q49: Model N-1
L51: KANTOR DESA/KELURAHAN | N51: : | O51: TAMBI
L52: KECAMATAN | N52: : | O52: WATUKUMPUL
L53: KABUPATEN/KOTA | N53: : | O53: PEMALANG
L56: SURAT KETERANGAN UNTUK NIKAH
L57: Nomor:474.2/ 36 / III / 2017
L59: Yang bertanda tangan dibawah ini menerangkan dengan sesungguhnya bahwa:
L61: 1. | M61: Nama lengkap dan alias | N61: : | O61: TATI SUNDARI
L62: 2. | M62: Jenis Kelamin | N62: : | O62: Perempuan
...

Sheet Form.N-2
F2: Lampiran PMA No.11 Tahun 2007 | P2: Lampiran PMA No.11 Tahun 2007
G3: -Pasal 5 ayat (2) huruf b | Q3: -Pasal 5 ayat (2) huruf b
G4: Model N- 2 | Q4: Model N- 2
B6: KANTOR DESA/KELURAHAN | D6: : | E6: TAMBI | L6: KANTOR DESA/KELURAHAN | N6: : | O6: TAMBI
B7: KECAMATAN | D7: : | E7: WATUKUMPUL | L7: KECAMATAN | N7: : | O7: WATUKUMPUL
B8: KABUPATEN/KOTA | D8: : | E8: PEMALANG | L8: KABUPATEN/KOTA | N8: : | O8: PEMALANG
B11: SURAT KETERANGAN UNTUK NIKAH | L11: SURAT KETERANGAN UNTUK NIKAH
B12: Nomor:474.2/ 235 / XI / 2017 | L12: Nomor:474.2/ / / 2017
B14: Yang bertanda tangan dibawah ini menerangkan dengan sesungguhnya bahwa: | L14: Yang bertanda tangan dibawah ini menerangkan dengan sesungguhnya bahwa:
B16: 1. | C16: Nama lengkap dan alias | D16: : | E16: AMAR MA'RUF | L16: 1. | M16: Nama lengkap dan alias | N16: : | O16: ..............................................................
B17: 2. | C17: Tempat dan tanggal lahir | D17: : | E17: ='Form.N-1'!E18 -> Pemalang,06 Mei 1988 | L17: 2. | M17: Tempat dan tanggal lahir | N17: : | O17: ..............................................................
B18: 3. | C18: Warganegara | D18: : | E18: Indonesia | L18: 3. | M18: Warganegara | N18: : | O18: Indonesia
B19: 4. | C19: Agama | D19: : | E19: Islam | L19: 4. | M19: Agama | N19: : | O19: Islam
B20: 5. | C20: Pekerjaan | D20: : | E20: Wiraswasta | L20: 5. | M20: Pekerjaan | N20: : | O20: ..............................................................
B21: 6. | C21: Tempat tinggal | D21: : | E21: Desa Tambi RT.006 RW.001 | L21: 6. | M21: Tempat tinggal | N21: : | O21: Desa Tambi RT.00 RW.00
B23: adalah benar anak kandung dari pernikahan seorang pria : | L23: adalah benar anak kandung dari pernikahan seorang pria :
B24: 1. | C24: Nama lengkap dan alias | D24: : | E24: TAMIARJA | L24: 1. | M24: Nama lengkap dan alias | N24: : | O24: ..............................................................
B25: 2. | C25: Tempat dan tanggal lahir | D25: : | E25: Pemalang,1 Juli 1958 | L25: 2. | M25: Tempat dan tanggal lahir | N25: : | O25: ..............................................................
B26: 3. | C26: Warganegara | D26: : | E26: Indonesia | L26: 3. | M26: Warganegara | N26: : | O26: Indonesia
B27: 4. | C27: Agama | D27: : | E27: Islam | L27: 4. | M27: Agama | N27: : | O27: Islam
B28: 5. | C28: Pekerjaan | D28: : | E28: Wiraswasta | L28: 5. | M28: Pekerjaan | N28: : | O28: ..............................................................
B29: 6. | C29: Tempat tinggal | D29: : | E29: Desa Tambi RT.006 RW.001 | L29: 6. | M29: Tempat tinggal | N29: : | O29: Desa Tambi RT.00 RW.00
B31: dengan seorang wanita: | L31: dengan seorang wanita:
B32: 1. | C32: Nama lengkap dan alias | D32: : | E32: SAMEAH | L32: 1. | M32: Nama lengkap dan alias | N32: : | O32: ..............................................................
B33: 2. | C33: Tempat dan tanggal lahir | D33: : | E33: Pemalang,1 Juli 1957 | L33: 2. | M33: Tempat dan tanggal lahir | N33: : | O33: ..............................................................
B34: 3. | C34: Warganegara | D34: : | E34: Indonesia | L34: 3. | M34: Warganegara | N34: : | O34: Indonesia
B35: 4. | C35: Agama | D35: : | E35: Islam | L35: 4. | M35: Agama | N35: : | O35: Islam
B36: 5. | C36: Pekerjaan | D36: : | E36: Mengurus Rumah Tangga | L36: 5. | M36: Pekerjaan | N36: : | O36: ..............................................................
B37: 6. | C37: Tempat tinggal | D37: : | E37: Desa Tambi RT.006 RW.001 | L37: 6. | M37: Tempat tinggal | N37: : | O37: Desa Tambi RT.00 RW.00
C39: Demikianlah,surat keterangan inii dibuat dengan mengingat sumpah jabatan dan | M39: Demikianlah,surat keterangan inii dibuat dengan mengingat sumpah jabatan dan
B40: untuk digunakan seperlunya. | L40: untuk digunakan seperlunya.
F42: Tambi, 28 Nopember 2017 | P42: Tambi,...........................20177
F44: Kepala Desa/Lurah Tambi | P44: Kepala Desa/Lurah Tambi
F48: S O B I Y A H | P48: S O B I Y A H
P52: Lampiran PMA No.11 Tahun 2007
Q53: -Pasal 5 ayat (2) huruf b
Q54: Model N- 2
L56: KANTOR DESA/KELURAHAN | N56: : | O56: TAMBI
L57: KECAMATAN | N57: : | O57: WATUKUMPUL
L58: KABUPATEN/KOTA | N58: : | O58: PEMALANG
...

Sheet Form. N-3
G2: Lampiran PMA No.11 Tahun 2007 | R2: Lampiran PMA No.11 Tahun 2007
H3: -Pasal 5 ayat (2) huruf c | S3: -Pasal 5 ayat (2) huruf c
H4: Model N- 3 | S4: Model N- 3
C6: SURAT PERSETUJUAN MEMPELAI | N6: SURAT PERSETUJUAN MEMPELAI
B9: Yang bertanda tangan dibawah ini: | M9: Yang bertanda tangan dibawah ini:
B10: I. | C10: Calon Suami: | M10: I. | N10: Calon Suami:
C11: 1. | D11: Nama lengkap dan alias | E11: : | F11: AMAR MA'RUF | N11: 1. | O11: Nama lengkap dan alias | P11: : | Q11: ..............................................................
C12: 2. | D12: Bin | F12: TAMIARJA | N12: 2. | O12: Bin
C13: 3. | D13: Tempat dan tanggal lahir | E13: : | F13: Pemalang,06 Mei 1988 | N13: 3. | O13: Tempat dan tanggal lahir | P13: : | Q13: ..............................................................
C14: 4. | D14: Warganegara | E14: : | F14: Indonesia | N14: 4. | O14: Warganegara | P14: : | Q14: Indonesia
C15: 5. | D15: Agama | E15: : | F15: Islam | N15: 5. | O15: Agama | P15: : | Q15: Islam
C16: 6. | D16: Pekerjaan | E16: : | F16: Wiraswasta | N16: 6. | O16: Pekerjaan | P16: : | Q16: ..............................................................
C17: 7. | D17: Tempat tinggal | E17: : | F17: Desa Tambi RT.006 RW.001 Kec,Watukumpul | N17: 7. | O17: Tempat tinggal | P17: : | Q17: Desa Tambi RT.00 RW.00
B19: I. | C19: Calon Istri: | M19: I. | N19: Calon Istri:
C20: 1. | D20: Nama lengkap dan alias | E20: : | F20: INDRA RUKMANA SARI | N20: 1. | O20: Nama lengkap dan alias | P20: : | Q20: ..............................................................
C21: 2. | D21: Bin | F21: H.SURAJI MARSONO | N21: 2. | O21: Bin
C22: 3. | D22: Tempat dan tanggal lahir | E22: : | F22: Beo,16 Nopember 1993 | N22: 3. | O22: Tempat dan tanggal lahir | P22: : | Q22: ..............................................................
C23: 4. | D23: Warganegara | E23: : | F23: Indonesia | N23: 4. | O23: Warganegara | P23: : | Q23: Indonesia
C24: 5. | D24: Agama | E24: : | F24: Islam | N24: 5. | O24: Agama | P24: : | Q24: Islam
C25: 6. | D25: Pekerjaan | E25: : | N25: 6. | O25: Pekerjaan | P25: : | Q25: ..............................................................
C26: 7. | D26: Tempat tinggal | E26: : | F26: Lingkungan 4, Kelurahan Beo Induk, Kecamatan Beo | N26: 7. | O26: Tempat tinggal | P26: : | Q26: Desa Tambi RT.00 RW.00
F27: Kabupaten Talaud, Prov.Sulawesi Utara
C29: Menyatakan dengan sesungguhnya bahwa atas dasar sekarela,dengan kesadaran sendiri,tanpa | N29: Menyatakan dengan sesungguhnya bahwa atas dasar sekarela,dengan kesadaran sendiri,tanpa
C30: paksaan dari siapapun juga,ssetuju untuk melangsungkan pernikahan. | N30: paksaan dari siapapun juga,ssetuju untuk melangsungkan pernikahan.
C31: Demikianlah,surat persetujuan ini di buat untuk digunakan seperlunya. | N31: Demikianlah,surat persetujuan ini di buat untuk digunakan seperlunya.
G33: Tambi,28 Nopember 2017 | R33: Tambi,...........................2017
C35: I. | D35: Calon Suami | G35: II. Calon Istri | N35: I. | O35: Calon Suami | R35: II. Calon Istri
D39: AMAR MA'RUF | G39: INDRA RUKMANA SARI | O39: (..................................................) | R39: (..................................................)
G84: Lampiran PMA No.11 Tahun 2007
H85: -Pasal 5 ayat (2) huruf c
H86: Model N- 3
C88: SURAT PERSETUJUAN MEMPELAI
B91: Yang bertanda tangan dibawah ini:
B92: I. | C92: Calon Suami:
C93: 1. | D93: Nama lengkap dan alias | E93: : | F93: TARSIMUN
C94: 2. | D94: Bin | F94: YASROWI
C95: 3. | D95: Tempat dan tanggal lahir | E95: : | F95: Purbalingga,13 Agustus 1973
C96: 4. | D96: Warganegara | E96: : | F96: Indonesia
C97: 5. | D97: Agama | E97: : | F97: Islam
C98: 6. | D98: Pekerjaan | E98: : | F98: Karyawan Swasta
...

Sheet Form.N - 4
R6: Lampiran PMA No.11 Tahun 2007
A7: PEMERINTAH KABUPATEN PEMALANG | S7: -Pasal 5 ayat (2) huruf d
A8: KECAMATAN WATUKUMPUL | S8: Model N - 4
A9: KEPALA DESA TAMBI
N10: KANTOR DESA/KELURAHAN | P10: : | Q10: TAMBI
N11: KECAMATAN | P11: : | Q11: WATUKUMPUL
A12: SURAT KETERANGAN/PENGANTAR | N12: KABUPATEN/KOTA | P12: : | Q12: PEMALANG
A13: 474.2 /294 /x/ 2023
N14: SURAT KETERANGAN TENTANG ORANG TUA
B16: Yang bertanda tangan dibawah ini, menerangkan seorang Laki-laki / Perempuan*): | M16: Yang bertanda tangan dibawah ini menerangkan dengan sesungguhnya bahwa:
B18: I. | C18: 1. | D18: Nama lengkap dan alias | E18: : | F18: DARTO | M18: I. | N18: 1. | O18: Nama lengkap dan alias | P18: : | Q18: ..............................................................
C19: 2. | D19: Bint | E19: : | F19: MUSERI
C20: 3. | D20: Tempat dan tanggal lahir | E20: : | F20: Pemalang,24 Mei 1996 | N20: 2. | O20: Tempat dan tanggal lahir | P20: : | Q20: ..............................................................
C21: 4. | D21: Warganegara/Agama | E21: : | F21: Indonesia /Islam | N21: 3. | O21: Warganegara | P21: : | Q21: Indonesia
C22: 5. | D22: Pekerjaan | E22: : | F22: Wiraswasta | N22: 5. | O22: Pekerjaan | P22: : | Q22: ..............................................................
C23: 6. | D23: Tempat tinggal | E23: : | F23: RT.009 RW.002 Desa Tambi,Kecamatan Watukumpul | N23: 6. | O23: Tempat tinggal | P23: : | Q23: Desa Tambi RT.00 RW.00
C24: 7. | D24: Surat Bukti Diri | E24: : | F24: KTP NO : 3327040307960004
F25: KK NO : 3327040202110009
C26: 8. | D26: Keperluan | E26: : | F26: Mendaftar Nikah/Boro Nikah*) Ke
F27: KUA KEC.KARANGMONCOL <KAB>
C29: 9. | D29: Berlaku | E29: : | F29: 13-11-2023 s/d Selesai
C30: 10. | D30: Keterangan Lain-lain | E30: : | F30: Orang Tersebut benar-benar warga Desa Tambi
F31: Kecamatan Watukumpul Kabupaten Pemalang
F32: dan Berstatus : JEJAKA
F33: dan akan menikah dengan :
F34: Nama : LEONITA DEWI ARiANTI
F35: Binti : SUDIONO
F36: NIK :3303124204040003
F37: Alamat : RT 004 RW 002 Desa Sirau Kec..Karangmoncol
F38: Kab..Purbalingga
D40: Demikianlah,surat keterangan inii dibuat dengan mengingat sumpah jabatan dan | O40: Demikianlah,surat keterangan inii dibuat dengan mengingat sumpah jabatan dan
B41: untuk digunakan seperlunya. | M41: untuk digunakan seperlunya.
G43: Tambi,11 Oktober 2023 | R43: Tambi,...........................2017
D45: Tanda Tangan Pemegang | G45: Kepala Desa Tambi | R45: Kepala Desa/Lurah Tambi
D49: DARTO | G49: J U R I | R49: S O B I Y A H
G90: Lampiran PMA No.11 Tahun 2007
H91: -Pasal 5 ayat (2) huruf d
H92: Model N - 4
C94: KANTOR DESA/KELURAHAN | E94: : | F94: TAMBI
C95: KECAMATAN | E95: : | F95: WATUKUMPUL
...

Sheet Form. N7
F2: Lampiran PMA No.11 Tahun 2007 | P2: Lampiran PMA No.11 Tahun 2007
G3: -Pasal 5 ayat (1) | Q3: -Pasal 5 ayat (1)
G4: Model N - 7 | Q4: Model N - 7
G6: Tambi,28 Noopember 2017 | P6: Tambi,...............................2017
B8: Lampiran | D8: : | E8: ........Lembar | F8: Kepada Yth, | L8: Lampiran | N8: : | O8: ........Lembar | P8: Kepada Yth,
B9: Prihal | D9: : | E9: Pemberitahuan Kehendak Nikah | F9: Kepala KUA Kecamatan/Penghulu/ | L9: Prihal | N9: : | O9: Pemberitahuan Kehendak Nikah | P9: Kepala KUA Kecamatan/Penghulu/
F10: Pembantu Penghulu | P10: Pembantu Penghulu
F11: di WATUKUMPUL | P11: di ....................................
B14: Assalamu'alaikum Wr.Wb. | L14: Assalamu'alaikum Wr.Wb.
D15: Dengan ini kami memberitahukan bahwa kami bermaksud akan melangsunggkan | N15: Dengan ini kami memberitahukan bahwa kami bermaksud akan melangsunggkan
B16: pernikahan antara AMAR MA'RUF dengan INDRA RUKMANA SARI pada hari....................... | L16: pernikahan antara ...............................dengan............. .....................pada hari..............................tanggal
B17: tanggal,................................. jam...................dengan mas kawin, ......................................dibayar tunai/ | L17: ......................jam...................dengan mas kawin, ...........................................................................dibayar tunai/
B18: hutang *) bertempat di Kantor KUA Kec.Beo ,Kab.Talaud,Prov.Sulawsi Utara. | L18: hutang *) bertempat di .................................................................................................
D19: Bersama ini kami lampirkan surat-surat yang diperlukan untuk diperiksa,sebagai | N19: Bersama ini kami lampirkan surat-surat yang diperlukan untuk diperiksa,sebagai
B20: berikut : | L20: berikut :
B22: 1. | C22: Surat Keterangan untuk Nikah , model N 1 | L22: 1. | M22: Surat Keterangan untuk Nikah , model N 1
B23: 2. | C23: Surat Keterangan Asal Usul , model N 2 | L23: 2. | M23: Surat Keterangan Asal Usul , model N 2
B24: 3. | C24: Surat Persetujuan Mempelai , model N 3 | L24: 3. | M24: Surat Persetujuan Mempelai , model N 3
B25: 4. | C25: Surat Keterangan tentang Orang Tua , model N 4 | L25: 4. | M25: Surat Keterangan tentang Orang Tua , model N 4
B26: 5. | C26: ............................................................................................ | L26: 5. | M26: ............................................................................................
B27: 6. | C27: ............................................................................................ | L27: 6. | M27: ............................................................................................
B28: 7. | C28: ............................................................................................ | L28: 7. | M28: ............................................................................................
B29: 8. | C29: ............................................................................................ | L29: 8. | M29: ............................................................................................
D31: Hanya dapat dihadiri dan dicatat pelaksanaannya sesuai dengan ketentuan perundang- | N31: Hanya dapat dihadiri dan dicatat pelaksanaannya sesuai dengan ketentuan perundang-
B32: undangan yang berlaku. | L32: undangan yang berlaku.
B34: Wassalam'ualaikum.Wr.Wb. | L34: Wassalam'ualaikum.Wr.Wb.
C38: diterima tanggal,............................... | M38: diterima tanggal,...............................
E39: Yang menerima | F39: Yang memberitahukan | O39: Yang menerima | P39: Yang memberitahukan
E40: Kepala KUA/Pengghulu/ | F40: Calon mempelai/Wali/Wakil Wali*) | O40: Kepala KUA/Pengghulu/ | P40: Calon mempelai/Wali/Wakil Wali*)
E41: Pemantu Penghulu*) | O41: Pemantu Penghulu*)
E45: .................................................. | F45: AMAR MA'RUF | O45: .................................................. | P45: ..................................................
F84: Lampiran PMA No.11 Tahun 2007
G85: -Pasal 5 ayat (1)
G86: Model N - 7
G88: Tambi,22 Maret 2017
B90: Lampiran | D90: : | E90: ........Lembar | F90: Kepada Yth,
B91: Prihal | D91: : | E91: Pemberitahuan Kehendak Nikah | F91: Kepala KUA Kecamatan/Penghulu/
F92: Pembantu Penghulu
F93: di WATUKUMPUL
B96: Assalamu'alaikum Wr.Wb.
...

Sheet Surat Kematian
B2: Pemerintah Kabupaten | D2: : | E2: PEMALANG
B3: Kecamatan | D3: : | E3: WATUKUMPUL
B4: Desa/Kelurahan | D4: : | E4: TAMBI
B7: UNTUK YANG BERSANGKUTAN
B10: SURAT KETERANGAN KEMATIAN
B12: No. : 474.3/420/VIII /2018
C15: Yang bertanda tangan dibawah ini,menerangkan
B16: bahwa :
B18: Nama lengkap | D18: : | E18: SAHURI
B20: NIK | D20: : | E20: 3327040107420041
B22: Jenis Kelamin | D22: : | E22: Laki - Laki
B24: Tgl lahir/Umur | D24: : | E24: Pemalang,10 Januari 1948
B26: Agama | D26: : | E26: Islam
B28: Alamat | D28: : | E28: Desa Tambi RT 011 RW 002
E29: Kecamatan Watukumpul Kab.Pemalang
B32: Telah meninggal dunia pada :
B34: Hari | D34: : | E34: KAMIS
B36: Tanggal | D36: : | E36: 43329
B38: Bertempat di | D38: : | E38: RUMAH
B40: Penyebab Kematian | D40: : | E40: SAKIT
B44: Surat keterangan ini dibuat berdasarkan keterangan pelapor :
B46: Nama lengkap | D46: : | E46: TARLIAH
B48: NIK | D48: : | E48: 3327044107500088
B50: Umur | D50: : | E50: 60 Tahun
B52: Pekerjaan | D52: : | E52: MENGURUS RUMAH TANGGA
B54: Alamat | D54: : | E54: Desa Tambi RT 011 RW 002
E55: Kecamatan Watukumpul Kab.Pemalang
B58: Hubungan pelapor dengan yang mati : Istri
E61: Tambi,19 Agustus 2018
E63: a.n. Kepala Desa Tambi
E64: SEKRETARIS DESA
E68: SARYONO
F136: Mengetahui :
F137: Kepala Desa Tambi
F141: S O B I Y A H

Sheet SUKET KEMATIAN B
Y1: KODE.F-2.29
B3: Pemerintah Desa/Kelurahan | D3: : | F3: Tambi | P3: Ket | R3: : | S3: Lembar 1 | V3: : | W3: Untuk yang bersangkutan
B4: Kecamatan | D4: : | F4: Watukumpul | S4: Lembar 2 | V4: : | W4: Untuk UPTD/Instansi Pelaksana
B5: Kabupaten/Kota | D5: : | F5: Pemalang | S5: Lembar 3 | V5: : | W5: Untuk Desa/Kelurahan
B6: Kode Wilayah | D6: : | F6: 3 | G6: 3 | H6: 2 | I6: 7 | J6: 0 | K6: 4 | L6: 0 | M6: 2 | N6: 0 | O6: 2 | P6: 2 | S6: Lembar 4 | V6: : | W6: Untuk Kecamatan
B8: SURAT KETERANGAN KEMATIAN
B9: 4No: 474.3 / 563 / I /2025
B11: Nama Kepala Keluarga | D11: : | F11: =MID(AH11,COLUMNS($AH$11:AH11),1) -> N | G11: =MID($AH$11,COLUMNS($AH$11:AI11),1) -> G | H11: =MID($AH$11,COLUMNS($AH$11:AJ11),1) -> A | I11: =MID($AH$11,COLUMNS($AH$11:AK11),1) -> L | J11: =MID($AH$11,COLUMNS($AH$11:AL11),1) -> I | K11: =MID($AH$11,COLUMNS($AH$11:AM11),1) -> M | L11: =MID($AH$11,COLUMNS($AH$11:AN11),1) -> A | M11: =MID($AH$11,COLUMNS($AH$11:AO11),1) -> N | N11: =MID($AH$11,COLUMNS($AH$11:AP11),1) | ... AD11: =MID($AH$11,COLUMNS($AH$11:BF11),1) | AF11: Nama Kepala Keluarga | AH11: NGALIMAN
B12: Nomor Kartu Keluarga | D12: : | F12: =MID(AH12,COLUMNS($AH$11:AH12),1) -> 3 | G12: =MID($AH12,COLUMNS($AH$11:AI12),1) -> 3 | H12: =MID($AH12,COLUMNS($AH$11:AJ12),1) -> 2 | I12: =MID($AH12,COLUMNS($AH$11:AK12),1) -> 7 | J12: =MID($AH12,COLUMNS($AH$11:AL12),1) -> 0 | K12: =MID($AH12,COLUMNS($AH$11:AM12),1) -> 4 | L12: =MID($AH12,COLUMNS($AH$11:AN12),1) -> 0 | M12: =MID($AH12,COLUMNS($AH$11:AO12),1) -> 3 | N12: =MID($AH12,COLUMNS($AH$11:AP12),1) -> 0 | ... AA12: =MID($AH12,COLUMNS($AH$11:BC12),1) | AB12: =MID($AH$12,COLUMNS($AH$12:BD12),1) | AC12: =MID($AH$12,COLUMNS($AH$12:BE12),1) | AD12: =MID($AH$12,COLUMNS($AH$12:BF12),1) | AF12: Nomor Kartu Keluarga | AH12: 3327040302110016
F13: =MID(AH13,COLUMNS($AH$11:AH13),1)
B14: JENAZAH | F14: =MID(AH14,COLUMNS($AH$11:AH14),1)
B15: 1. | C15: NIK | D15: : | F15: =MID($AH$15,COLUMNS($AH$11:AH15),1) -> 3 | G15: =MID($AH$15,COLUMNS($AH$11:AI15),1) -> 3 | H15: =MID($AH$15,COLUMNS($AH$11:AJ15),1) -> 2 | I15: =MID($AH$15,COLUMNS($AH$11:AK15),1) -> 7 | J15: =MID($AH$15,COLUMNS($AH$11:AL15),1) -> 0 | K15: =MID($AH$15,COLUMNS($AH$11:AM15),1) -> 4 | L15: =MID($AH$15,COLUMNS($AH$11:AN15),1) -> 5 | M15: =MID($AH$15,COLUMNS($AH$11:AO15),1) -> 5 | ... U15: =MID($AH$15,COLUMNS($AH$11:AW15),1) -> 2 | AF15: NIK | AH15: 3327045507120002
B16: 2. | C16: Nama Lengkap | D16: : | F16: =MID($AH$16,COLUMNS($AH$16:AH16),1) -> N | G16: =MID($AH$16,COLUMNS($AH$16:AI16),1) -> U | H16: =MID($AH$16,COLUMNS($AH$16:AJ16),1) -> R | I16: =MID($AH$16,COLUMNS($AH$16:AK16),1) | J16: =MID($AH$16,COLUMNS($AH$16:AL16),1) -> S | K16: =MID($AH$16,COLUMNS($AH$16:AM16),1) -> A | L16: =MID($AH$16,COLUMNS($AH$16:AN16),1) -> N | M16: =MID($AH$16,COLUMNS($AH$16:AO16),1) -> T | ... U16: =MID($AH$16,COLUMNS($AH$16:AW16),1) | AF16: Nama Lengkap | AH16: NUR SANTIKA
B17: 3. | C17: Jenis Kelamin | D17: : | F17: =AH17 -> 1 | G17: 1.Laki-laki | M17: =AI17 -> 2 | N17: 2. Perempuan | AF17: Jenis Kelamin | AH17: 1 | AI17: 2
B18: 4. | C18: Tanggal Lahir/Umur | D18: : | F18: Tgl | H18: =MID($AI$18,COLUMNS($AH$18:AH18),1) -> 1 | I18: =MID($AI$18,COLUMNS($AH$18:AI18),1) -> 5 | J18: Bln. | M18: =MID($AL$18,COLUMNS($AL$18:AL18),1) -> 0 | N18: =MID($AL$18,COLUMNS($AL$18:AM18),1) -> 7 | O18: Tahun | R18: =MID($AO$18,COLUMNS($AO$18:AO18),1) -> 2 | S18: =MID($AO$18,COLUMNS($AO$18:AP18),1) -> 0 | T18: =MID($AO$18,COLUMNS($AO$18:AQ18),1) -> 1 | U18: =MID($AO$18,COLUMNS($AO$18:AR18),1) -> 2 | V18: Umur | Y18: 0 | Z18: =MID($AS$18,COLUMNS($AS$18:AS18),1) -> 1 | AA18: =MID($AS$18,COLUMNS($AS$18:AT18),1) -> 2 | AF18: Tanggal Lahir/Umur | AI18: 15 | AK18: / | AL18: 07 | AN18: / | AO18: 2012 | AS18: =2024-AO18 -> 12
B19: 5. | C19: Tempat Lahir | D19: : | F19: =MID($AH$19,COLUMNS($AH$16:AH16),1) -> P | G19: =MID($AH$19,COLUMNS($AH$16:AI16),1) -> E | H19: =MID($AH$19,COLUMNS($AH$16:AJ16),1) -> M | I19: =MID($AH$19,COLUMNS($AH$16:AK16),1) -> A | J19: =MID($AH$19,COLUMNS($AH$16:AL16),1) -> L | K19: =MID($AH$19,COLUMNS($AH$16:AM16),1) -> A | L19: =MID($AH$19,COLUMNS($AH$16:AN16),1) -> N | M19: =MID($AH$19,COLUMNS($AH$16:AO16),1) -> G | ... O19: =MID($AH$19,COLUMNS($AH$16:AQ16),1) | R19: Kode Prov. | V19: 3 | W19: 3 | X19: Kode Kab. | AB19: 2 | AC19: 7 | AF19: Tempat Lahir | AH19: PEMALANG
B20: 6. | C20: Agama | D20: : | F20: 1 | G20: 1. Islam | K20: 2.Kristen | O20: 3.Katolik | S20: 4.Hindu | W20: 5.Budha | Z20: 6.Lainnya | AF20: Agama
B21: 7. | C21: Pekerjaan | D21: : | F21: =MID($AH$21,COLUMNS($AH$21:AH21),1) -> 0 | G21: =MID($AH$21,COLUMNS($AH$21:AI21),1) -> 1 | AF21: Pekerjaan | AH21: 01
B22: 8. | C22: Alamat | D22: : | F22: =AH22 -> TAMBI RT 008 RW 002 KEC WATUKUMPUL KAB PEMALANG | AF22: Alamat | AH22: TAMBI RT 008 RW 002 KEC WATUKUMPUL KAB PEMALANG
F23: a. Desa/Kelurahan | L23: TAMBI | T23: c.Kab/Kota | X23: PEMALANG
F24: b. Kecamatan | L24: WATUKUMPUL | T24: d.Provinsi | X24: JAWA TENGAH
B25: 9. | C25: Anak ke | D25: : | F25: 1 | G25: 1. | J25: 2. | M25: 3. | P25: 4…....... | AF25: Anak ke
B26: 10. | C26: Tanggal Kematian | D26: : | F26: Tgl | H26: =MID($AI$26,COLUMNS($AH$16:AH16),1) -> 2 | I26: =MID($AI$26,COLUMNS($AH$16:AI16),1) -> 4 | J26: Bln | M26: =MID($AL$26,COLUMNS($AL$26:AL26),1) -> 0 | N26: =MID($AL$26,COLUMNS($AL$26:AM26),1) -> 1 | O26: Tahun | R26: =MID($AO$26,COLUMNS($AL$26:AL26),1) -> 2 | S26: =MID($AO$26,COLUMNS($AL$26:AM26),1) -> 0 | T26: =MID($AO$26,COLUMNS($AL$26:AN26),1) -> 2 | U26: =MID($AO$26,COLUMNS($AL$26:AO26),1) -> 4 | AF26: Tanggal Kematian | AI26: 24 | AK26: / | AL26: 01 | AN26: / | AO26: 2024
B27: 11. | C27: Pukul | D27: : | F27: =MID($AI27,COLUMNS($AL$26:AL26),1) -> 1 | G27: =MID($AI27,COLUMNS($AL$26:AM26),1) -> 5 | H27: =MID($AI27,COLUMNS($AL$26:AN26),1) -> 1 | I27: =MID($AI27,COLUMNS($AL$26:AO26),1) -> 5 | AF27: Pukul | AI27: 1515
B28: 12. | C28: Sebab Kematian | D28: : | F28: 1 | G28: 1.Sakit biasa/Tua | P28: 2.Wabah Penyakit | X28: 3.Kecelakaan | AF28: Sebab Kematian
G29: 4.Kriminalisasi | P29: 5.Bunuh Diri | X29: 6.Lainnya
B30: 13. | C30: Tempat Kematian | D30: : | F30: =MID($AH$30,COLUMNS($AH$30:AH30),1) -> R | G30: =MID($AH$30,COLUMNS($AH$30:AI30),1) -> U | H30: =MID($AH$30,COLUMNS($AH$30:AJ30),1) -> M | I30: =MID($AH$30,COLUMNS($AH$30:AK30),1) -> A | J30: =MID($AH$30,COLUMNS($AH$30:AL30),1) -> H | K30: =MID($AH$30,COLUMNS($AH$30:AM30),1) | L30: =MID($AH$30,COLUMNS($AH$30:AN30),1) | M30: =MID($AH$30,COLUMNS($AH$30:AO30),1) | ... U30: =MID($AH$30,COLUMNS($AH$30:AW30),1) | AF30: Tempat Kematian | AH30: RUMAH
B31: 14. | C31: Yang menerangkan | D31: : | F31: 2 | G31: 1.Dokter | L31: 2.Tenaga Kesehatan | T31: 3.Kepolisian | Y31: 4.Lainnya
B33: AYAH | AF33: AYAH
B34: 1. | C34: NIK | F34: =MID($AH$34,COLUMNS($AH$34:AH34),1) -> 3 | G34: =MID($AH$34,COLUMNS($AH$34:AI34),1) -> 3 | H34: =MID($AH$34,COLUMNS($AH$34:AJ34),1) -> 2 | I34: =MID($AH$34,COLUMNS($AH$34:AK34),1) -> 7 | J34: =MID($AH$34,COLUMNS($AH$34:AL34),1) -> 0 | K34: =MID($AH$34,COLUMNS($AH$34:AM34),1) -> 4 | L34: =MID($AH$34,COLUMNS($AH$34:AN34),1) -> 0 | M34: =MID($AH$34,COLUMNS($AH$34:AO34),1) -> 7 | ... U34: =MID($AH$34,COLUMNS($AH$34:AW34),1) -> 4 | AF34: NIK | AH34: 3327040705840004
B35: 2. | C35: Nama Lengkap | F35: =MID($AH$35,COLUMNS($AH$35:AH35),1) -> N | G35: =MID($AH$35,COLUMNS($AH$35:AI35),1) -> G | H35: =MID($AH$35,COLUMNS($AH$35:AJ35),1) -> A | I35: =MID($AH$35,COLUMNS($AH$35:AK35),1) -> L | J35: =MID($AH$35,COLUMNS($AH$35:AL35),1) -> I | K35: =MID($AH$35,COLUMNS($AH$35:AM35),1) -> M | L35: =MID($AH$35,COLUMNS($AH$35:AN35),1) -> A | M35: =MID($AH$35,COLUMNS($AH$35:AO35),1) -> N | ... U35: =MID($AH$35,COLUMNS($AH$35:AW35),1) | AF35: Nama Lengkap | AH35: NGALIMAN
B36: 3. | C36: Tanggal Lahir/Umur | F36: Tgl | H36: =MID($AI$36,COLUMNS($AH$35:AH35),1) -> 0 | I36: =MID($AI$36,COLUMNS($AH$35:AI35),1) -> 7 | J36: Bln. | M36: =MID($AL$36,COLUMNS($AH$35:AH35),1) -> 0 | N36: =MID($AL$36,COLUMNS($AH$35:AI35),1) -> 5 | O36: Tahun | R36: =MID($AO$36,COLUMNS($AH$35:AH35),1) -> 1 | S36: =MID($AO$36,COLUMNS($AH$35:AI35),1) -> 9 | T36: =MID($AO$36,COLUMNS($AH$35:AJ35),1) -> 8 | U36: =MID($AO$36,COLUMNS($AH$35:AK35),1) -> 4 | V36: Umur | Y36: 0 | Z36: =MID($AS$36,COLUMNS($AH$35:AH35),1) -> 4 | AA36: =MID($AS$36,COLUMNS($AH$35:AI35),1) -> 0 | AF36: Tanggal Lahir/Umur | AI36: 07 | AL36: 05 | AO36: 1984 | AS36: =2024-AO36 -> 40
B37: 4. | C37: Pekerjaan | F37: =MID($AH$37,COLUMNS($AH$37:AH37),1) -> 0 | G37: =MID($AH$37,COLUMNS($AH$37:AI37),1) -> 8 | AF37: Pekerjaan | AH37: 08
B38: 5. | C38: Alamat | F38: =AH38 -> TAMBI RT 008 RW 002 KEC WATUKUMPUL KAB PEMALANG | AF38: Alamat | AH38: TAMBI RT 008 RW 002 KEC WATUKUMPUL KAB PEMALANG
F39: a. Desa/Kelurahan | L39: TAMBI | T39: c.Kab/Kota | X39: PEMALANG
F40: b. Kecamatan | L40: WATUKUMPUL | T40: d.Provinsi | X40: JAWA TENGAH
B42: IBU | AF42: IBU
B43: 1. | C43: NIK | F43: =MID($AH$43,COLUMNS($AH$43:AH43),1) -> 3 | G43: =MID($AH$43,COLUMNS($AH$43:AI43),1) -> 3 | H43: =MID($AH$43,COLUMNS($AH$43:AJ43),1) -> 2 | I43: =MID($AH$43,COLUMNS($AH$43:AK43),1) -> 7 | J43: =MID($AH$43,COLUMNS($AH$43:AL43),1) -> 0 | K43: =MID($AH$43,COLUMNS($AH$43:AM43),1) -> 4 | L43: =MID($AH$43,COLUMNS($AH$43:AN43),1) -> 4 | M43: =MID($AH$43,COLUMNS($AH$43:AO43),1) -> 4 | ... U43: =MID($AH$43,COLUMNS($AH$43:AW43),1) -> 0 | AF43: NIK | AH43: 3327044401900010
B44: 2. | C44: Nama Lengkap | F44: =MID($AH$44,COLUMNS($AH$44:AH44),1) -> K | G44: =MID($AH$44,COLUMNS($AH$44:AI44),1) -> H | H44: =MID($AH$44,COLUMNS($AH$44:AJ44),1) -> O | I44: =MID($AH$44,COLUMNS($AH$44:AK44),1) -> T | J44: =MID($AH$44,COLUMNS($AH$44:AL44),1) -> I | K44: =MID($AH$44,COLUMNS($AH$44:AM44),1) -> J | L44: =MID($AH$44,COLUMNS($AH$44:AN44),1) -> A | M44: =MID($AH$44,COLUMNS($AH$44:AO44),1) -> H | ... V44: =MID($AH$44,COLUMNS($AH$44:AX44),1) | AF44: Nama Lengkap | AH44: KHOTIJAH
B45: 3. | C45: Tanggal Lahir/Umur | F45: Tgl | H45: =MID($AI$45,COLUMNS($AH$34:AH34),1) -> 0 | I45: =MID($AI$45,COLUMNS($AH$34:AI34),1) -> 4 | J45: Bln. | M45: =MID($AL$45,COLUMNS($AH$34:AH34),1) -> 0 | N45: =MID($AL$45,COLUMNS($AH$34:AI34),1) -> 1 | O45: Tahun | R45: =MID($AO$45,COLUMNS($AH$34:AH34),1) -> 1 | S45: =MID($AO$45,COLUMNS($AH$34:AI34),1) -> 9 | T45: =MID($AO$45,COLUMNS($AH$34:AJ34),1) -> 9 | U45: =MID($AO$45,COLUMNS($AH$34:AK34),1) -> 0 | V45: Umur | Y45: =MID($AS$45,COLUMNS($AS$45:AS45),1) -> 3 | Z45: =MID($AS$45,COLUMNS($AS$45:AT45),1) -> 4 | AA45: =MID($AS$45,COLUMNS($AS$45:AU45),1) | AF45: Tanggal Lahir/Umur | AI45: 04 | AL45: 01 | AO45: 1990 | AS45: =2024-AO45 -> 34
...

Sheet Surat Kelahiran
X2: KODE.F-2.01
A4: Desa/Kelurahan | D4: : | E4: TAMBI | T4: Ket: | U4: Lembar 1 | W4: : | X4: Untuk yang bersangkutan | AF4: Desa/Kelurahan
A5: Kecamatan | D5: : | E5: WATUKUMPUL | U5: Lembar 2 | W5: : | X5: Desa/Kelurahan | AF5: Kecamatan
A6: Pemerintah Kabupaten | D6: : | E6: PEMALANG | U6: Lembar 3 | W6: : | X6: Kecamatan | AF6: Pemerintah Kabupaten
A8: Kode Wilayah | D8: : | E8: 3 | F8: 3 | G8: 2 | H8: 7 | I8: 0 | J8: 4 | K8: 0 | L8: 1 | M8: 1 | AF8: Kode Wilayah
A10: SURAT KETERANGAN KELAHIRAN
A12: No : 400.12.3.1/003/VII/2026
A14: Nama Kepala Keluarga | D14: : | E14: =MID($AI14,COLUMNS($AI14:AI14),1) -> B | F14: =MID($AI14,COLUMNS($AI14:AJ14),1) -> U | G14: =MID($AI14,COLUMNS($AI14:AK14),1) -> D | H14: =MID($AI14,COLUMNS($AI14:AL14),1) -> I | I14: =MID($AI14,COLUMNS($AI14:AM14),1) -> A | J14: =MID($AI14,COLUMNS($AI14:AN14),1) -> N | K14: =MID($AI14,COLUMNS($AI14:AO14),1) -> T | L14: =MID($AI14,COLUMNS($AI14:AP14),1) -> O | ... AC14: =MID($AI14,COLUMNS($AI14:BG14),1) | AF14: Nama Kepala Keluarga | AI14: ='ISIAN DATA'!E6 -> BUDIANTO
A15: Nomor Kartu Keluarga | D15: : | E15: =MID($AI15,COLUMNS($AI15:AI15),1) -> 3 | F15: =MID($AI15,COLUMNS($AI15:AJ15),1) -> 3 | G15: =MID($AI15,COLUMNS($AI15:AK15),1) -> 2 | H15: =MID($AI15,COLUMNS($AI15:AL15),1) -> 7 | I15: =MID($AI15,COLUMNS($AI15:AM15),1) -> 0 | J15: =MID($AI15,COLUMNS($AI15:AN15),1) -> 4 | K15: =MID($AI15,COLUMNS($AI15:AO15),1) -> 2 | L15: =MID($AI15,COLUMNS($AI15:AP15),1) -> 3 | ... W15: =MID($AI15,COLUMNS($AI15:BA15),1) | AF15: Nomor Kartu Keluarga | AI15: ='ISIAN DATA'!E7 -> 3327042311210005
AI16: ='ISIAN DATA'!E8 -> 0
A17: BAYI/ANAK | AF17: BAYI/ANAK | AI17: ='ISIAN DATA'!E9 -> 0
AI18: ='ISIAN DATA'!E10 -> 0
A19: 1. | B19: Nama | D19: : | E19: =MID($AI19,COLUMNS($AI19:AI19),1) -> K | F19: =MID($AI19,COLUMNS($AI19:AJ19),1) -> H | G19: =MID($AI19,COLUMNS($AI19:AK19),1) -> A | H19: =MID($AI19,COLUMNS($AI19:AL19),1) -> L | I19: =MID($AI19,COLUMNS($AI19:AM19),1) -> I | J19: =MID($AI19,COLUMNS($AI19:AN19),1) -> F | K19: =MID($AI19,COLUMNS($AI19:AO19),1) -> A | L19: =MID($AI19,COLUMNS($AI19:AP19),1) | ... AC19: =MID($AI19,COLUMNS($AI19:BG19),1) -> I | AF19: 1. | AG19: Nama | AI19: ='ISIAN DATA'!E11 -> KHALIFA SYAKILA RAMADHANI
A20: 2. | B20: Jenis Kelamin | D20: : | E20: =AI20 -> 2 | F20: 1. Laki-laki | J20: 2. Perempuan | AF20: 2. | AG20: Jenis Kelamin | AI20: ='ISIAN DATA'!E12 -> 2
A21: 3. | B21: Tempat dilahirkan | D21: : | E21: 2 | F21: 1.RS/RB | J21: 2.Puskesmas | N21: 3.Polindes | R21: 4.Rumah | W21: 5.Lainnya | AF21: 3. | AG21: Tempat dilahirkan | AI21: ='ISIAN DATA'!E13 -> 0
A22: 4. | B22: Tempat Kelahiran | D22: : | E22: =MID($AI22,COLUMNS($AI22:AI22),1) -> P | F22: =MID($AI22,COLUMNS($AI22:AJ22),1) -> E | G22: =MID($AI22,COLUMNS($AI22:AK22),1) -> M | H22: =MID($AI22,COLUMNS($AI22:AL22),1) -> A | I22: =MID($AI22,COLUMNS($AI22:AM22),1) -> L | J22: =MID($AI22,COLUMNS($AI22:AN22),1) -> A | K22: =MID($AI22,COLUMNS($AI22:AO22),1) -> N | L22: =MID($AI22,COLUMNS($AI22:AP22),1) -> G | ... T22: =MID($AI22,COLUMNS($AI22:AX22),1) | AF22: 4. | AG22: Tempat Kelahiran | AI22: ='ISIAN DATA'!E14 -> PEMALANG
A23: 5. | B23: Hari dan Tanggal lahir | D23: : | E23: =MID($AI23,COLUMNS($AI23:AI23),1) -> 0 | F23: =MID($AI23,COLUMNS($AI23:AJ23),1) | G23: =MID($AI23,COLUMNS($AI23:AK23),1) | H23: =MID($AI23,COLUMNS($AI23:AL23),1) | I23: =MID($AI23,COLUMNS($AI23:AM23),1) | J23: =MID($AI23,COLUMNS($AI23:AN23),1) | K23: =MID($AI23,COLUMNS($AI23:AO23),1) | L23: =MID($AI23,COLUMNS($AI23:AP23),1) | N23: Tgl | P23: =MID($AJ$24,COLUMNS($AJ$24:AJ24),1) -> 0 | Q23: =MID($AJ$24,COLUMNS($AJ$24:AK24),1) -> 3 | S23: Bln | U23: =MID($AK$24,COLUMNS($AK$24:AK24),1) -> 0 | V23: =MID($AK$24,COLUMNS($AK$24:AL24),1) -> 4 | X23: Thn | Z23: =MID($AL$24,COLUMNS($AL$24:AL24),1) -> 2 | AA23: =MID($AL$24,COLUMNS($AL$24:AM24),1) -> 0 | AB23: =MID($AL$24,COLUMNS($AL$24:AN24),1) -> 2 | AC23: =MID($AL$24,COLUMNS($AL$24:AO24),1) -> 2 | AF23: 5. | AG23: Hari dan Tanggal lahir | AI23: ='ISIAN DATA'!E15 -> 0 | AJ23: TGL | AK23: BLN | AL23: THN | AM23: UMUR
A24: 6. | B24: Pukul | D24: : | E24: =MID($AI24,COLUMNS($AI24:AI24),1) -> 0 | F24: =MID($AI24,COLUMNS($AI24:AJ24),1) -> 9 | G24: =MID($AI24,COLUMNS($AI24:AK24),1) -> 0 | H24: =MID($AI24,COLUMNS($AI24:AL24),1) -> 0 | I24: WIB | AF24: 6. | AG24: Pukul | AI24: ='ISIAN DATA'!E16 -> 0900 | AJ24: ='ISIAN DATA'!F16 -> 03 | AK24: ='ISIAN DATA'!G16 -> 04 | AL24: ='ISIAN DATA'!H16 -> 2022 | AM24: ='ISIAN DATA'!I16 -> 4
A25: 7. | B25: Jenis Kelahiran | D25: : | E25: 1 | F25: 1.Tunggal | J25: 2.Kembar 2 | N25: 3.Kembar 3 | R25: 4.Kembar 4 | W25: 5.Lainnya | AF25: 7. | AG25: Jenis Kelahiran/ TANGGAL | AI25: ='ISIAN DATA'!E17 -> 0 | AJ25: ='ISIAN DATA'!F17 -> 0 | AK25: ='ISIAN DATA'!G17 -> 0 | AL25: ='ISIAN DATA'!H17 -> 0 | AM25: ='ISIAN DATA'!I17
A26: 8. | B26: Kelahiran Ke | D26: : | E26: =AI26 -> 1 | F26: 1. | G26: 2. | H26: 3. | I26: 4. | J26: ............................. | AF26: 8. | AG26: Kelahiran Ke | AI26: ='ISIAN DATA'!E18 -> 1 | AJ26: ='ISIAN DATA'!F18 -> 0 | AK26: ='ISIAN DATA'!G18 -> 0 | AL26: ='ISIAN DATA'!H18 -> 0 | AM26: ='ISIAN DATA'!I18
A27: 9. | B27: Penolong Kelahiran | D27: : | E27: 2 | F27: 1.Dokter | J27: 2.Bidan/Perawat | N27: 3.Dukun | R27: 4.Lainnya | AF27: 9. | AG27: Penolong Kelahiran | AI27: ='ISIAN DATA'!E19 | AJ27: ='ISIAN DATA'!F19 -> 0 | AK27: ='ISIAN DATA'!G19 -> 0 | AL27: ='ISIAN DATA'!H19 -> 0 | AM27: ='ISIAN DATA'!I19
A28: 10. | B28: Berat Bayi | D28: : | E28: =MID($AI$28,COLUMNS($AI$28:AI28),1) -> 3 | F28: =MID($AI$28,COLUMNS($AI$28:AJ28),1) -> 0 | G28: =MID($AI$28,COLUMNS($AI$28:AK28),1) -> 0 | H28: =MID($AI$28,COLUMNS($AI$28:AL28),1) -> 0 | I28: gr | AF28: 10. | AG28: Berat Bayi | AI28: ='ISIAN DATA'!E20 -> 3000 | AJ28: ='ISIAN DATA'!F20 -> 0 | AK28: ='ISIAN DATA'!G20 -> 0 | AL28: ='ISIAN DATA'!H20 -> 0 | AM28: ='ISIAN DATA'!I20
A29: 11. | B29: Panjang Bayi | D29: : | E29: =MID($AI$29,COLUMNS($AI$29:AI29),1) -> 4 | F29: =MID($AI$29,COLUMNS($AI$29:AJ29),1) -> 8 | G29: Cm | AF29: 11. | AG29: Panjang Bayi | AI29: ='ISIAN DATA'!E21 -> 48 | AJ29: ='ISIAN DATA'!F21 -> 0 | AK29: ='ISIAN DATA'!G21 -> 0 | AL29: ='ISIAN DATA'!H21 -> 0 | AM29: ='ISIAN DATA'!I21
AI30: ='ISIAN DATA'!E22 -> 0 | AJ30: ='ISIAN DATA'!F22 -> 0 | AK30: ='ISIAN DATA'!G22 -> 0 | AL30: ='ISIAN DATA'!H22 -> 0 | AM30: ='ISIAN DATA'!I22
A31: IBU | AF31: IBU | AI31: ='ISIAN DATA'!E23 -> 0 | AJ31: ='ISIAN DATA'!F23 -> 0 | AK31: ='ISIAN DATA'!G23 -> 0 | AL31: ='ISIAN DATA'!H23 -> 0 | AM31: ='ISIAN DATA'!I23
A32: 1. | B32: NIK | D32: : | E32: =MID($AI$32,COLUMNS($AI$32:AI32),1) -> 3 | F32: =MID($AI$32,COLUMNS($AI$32:AJ32),1) -> 3 | G32: =MID($AI$32,COLUMNS($AI$32:AK32),1) -> 2 | H32: =MID($AI$32,COLUMNS($AI$32:AL32),1) -> 7 | I32: =MID($AI$32,COLUMNS($AI$32:AM32),1) -> 0 | J32: =MID($AI$32,COLUMNS($AI$32:AN32),1) -> 4 | K32: =MID($AI$32,COLUMNS($AI$32:AO32),1) -> 7 | L32: =MID($AI$32,COLUMNS($AI$32:AP32),1) -> 1 | ... U32: =MID($AI$32,COLUMNS($AI$32:AY32),1) | AF32: 1. | AG32: NIK | AI32: ='ISIAN DATA'!E24 -> 3327047103960002 | AJ32: ='ISIAN DATA'!F24 -> 0 | AK32: ='ISIAN DATA'!G24 -> 0 | AL32: ='ISIAN DATA'!H24 -> 0 | AM32: ='ISIAN DATA'!I24
A33: 2. | B33: Nama Lengkap | D33: : | E33: =MID($AI$33,COLUMNS($AI$33:AI33),1) -> K | F33: =MID($AI$33,COLUMNS($AI$33:AJ33),1) -> H | G33: =MID($AI$33,COLUMNS($AI$33:AK33),1) -> A | H33: =MID($AI$33,COLUMNS($AI$33:AL33),1) -> F | I33: =MID($AI$33,COLUMNS($AI$33:AM33),1) -> S | J33: =MID($AI$33,COLUMNS($AI$33:AN33),1) -> O | K33: =MID($AI$33,COLUMNS($AI$33:AO33),1) -> H | L33: =MID($AI$33,COLUMNS($AI$33:AP33),1) | ... W33: =MID($AI$33,COLUMNS($AI$33:BA33),1) | AF33: 2. | AG33: Nama Lengkap | AI33: ='ISIAN DATA'!E25 -> KHAFSOH | AJ33: ='ISIAN DATA'!F25 -> TGL | AK33: ='ISIAN DATA'!G25 -> BLN | AL33: ='ISIAN DATA'!H25 -> THN | AM33: ='ISIAN DATA'!I25 -> UMUR
A34: 3. | B34: Tanggal lahir/Umur | D34: : | E34: Tgl | F34: =MID($AJ$34,COLUMNS($AJ$34:AJ34),1) -> 3 | G34: =MID($AJ$34,COLUMNS($AJ$34:AK34),1) -> 1 | I34: Bln. | J34: =MID($AK$34,COLUMNS($AK$34:AK34),1) -> 0 | K34: =MID($AK$34,COLUMNS($AK$34:AL34),1) -> 3 | M34: Thn. | N34: =MID($AL$34,COLUMNS($AL$34:AL34),1) -> 1 | O34: =MID($AL$34,COLUMNS($AL$34:AM34),1) -> 9 | P34: =MID($AL$34,COLUMNS($AL$34:AN34),1) -> 9 | Q34: =MID($AL$34,COLUMNS($AL$34:AO34),1) -> 6 | S34: Umur | U34: =MID($AM$34,COLUMNS($AM$34:AM34),1) -> 3 | V34: =MID($AM$34,COLUMNS($AM$34:AN34),1) -> 0 | AF34: 3. | AG34: Tanggal lahir/Umur | AI34: ='ISIAN DATA'!E26 -> 0 | AJ34: ='ISIAN DATA'!F26 -> 31 | AK34: ='ISIAN DATA'!G26 -> 03 | AL34: ='ISIAN DATA'!H26 -> 1996 | AM34: ='ISIAN DATA'!I26 -> 30
A35: 4. | B35: Pekerjaan | D35: : | E35: 0 | F35: 1 | AF35: 4. | AG35: Pekerjaan | AI35: ='ISIAN DATA'!E27 -> 01 | AJ35: ='ISIAN DATA'!F27 -> 0 | AK35: ='ISIAN DATA'!G27 -> 0 | AL35: ='ISIAN DATA'!H27 -> 0 | AM35: ='ISIAN DATA'!I27
A36: 5. | B36: Alamat | D36: : | E36: =AI36 -> RT 004 / 004 DESA TAMBI | AF36: 5. | AG36: Alamat | AI36: ='ISIAN DATA'!E28 -> RT 004 / 004 DESA TAMBI | AJ36: ='ISIAN DATA'!F28 -> 0 | AK36: ='ISIAN DATA'!G28 -> 0 | AL36: ='ISIAN DATA'!H28 -> 0 | AM36: ='ISIAN DATA'!I28
E37: a.Desa/Kelurahan | J37: TAMBI | P37: c.Kab./Kota | T37: PEMALANG | AI37: ='ISIAN DATA'!E29 -> 0 | AJ37: ='ISIAN DATA'!F29 -> 0 | AK37: ='ISIAN DATA'!G29 -> 0 | AL37: ='ISIAN DATA'!H29 -> 0 | AM37: ='ISIAN DATA'!I29
E38: b.Kecamatan | J38: WATUKUMPUL | P38: d.Provinsi | T38: JAWA TENGAH | AI38: ='ISIAN DATA'!E30 -> 0 | AJ38: ='ISIAN DATA'!F30 -> 0 | AK38: ='ISIAN DATA'!G30 -> 0 | AL38: ='ISIAN DATA'!H30 -> 0 | AM38: ='ISIAN DATA'!I30
A39: 6. | B39: Kewarganegaraan | D39: : | E39: 1. | G39: 1.WNI | J39: 2.WNA | AF39: 6. | AG39: Kewarganegaraan | AI39: ='ISIAN DATA'!E31 -> 0 | AJ39: ='ISIAN DATA'!F31 -> 0 | AK39: ='ISIAN DATA'!G31 -> 0 | AL39: ='ISIAN DATA'!H31 -> 0 | AM39: ='ISIAN DATA'!I31
A40: 7. | B40: Kebangsaan | D40: : | E40: INDONESIA | AF40: 7. | AG40: Kebangsaan | AI40: ='ISIAN DATA'!E32 -> INDONESIA | AJ40: ='ISIAN DATA'!F32 -> 0 | AK40: ='ISIAN DATA'!G32 -> 0 | AL40: ='ISIAN DATA'!H32 -> 0 | AM40: ='ISIAN DATA'!I32
A41: 8. | B41: Tgl.Pencatatan Perkawinan | D41: : | E41: Tgl. | G41: =MID($AJ$42,COLUMNS($AJ$42:AJ42),1) -> 1 | H41: =MID($AJ$42,COLUMNS($AJ$42:AK42),1) -> 0 | L41: =MID($AK$42,COLUMNS($AK$42:AK42),1) -> 0 | M41: =MID($AK$42,COLUMNS($AK$42:AL42),1) -> 8 | Q41: =MID($AL$42,COLUMNS($AL$42:AL42),1) -> 2 | R41: =MID($AL$42,COLUMNS($AL$42:AM42),1) -> 0 | S41: =MID($AL$42,COLUMNS($AL$42:AN42),1) -> 2 | T41: =MID($AL$42,COLUMNS($AL$42:AO42),1) -> 0 | AF41: 8. | AG41: Tgl.Pencatatan Perkawinan | AI41: ='ISIAN DATA'!E33 -> 0 | AJ41: ='ISIAN DATA'!F33 -> TGL | AK41: ='ISIAN DATA'!G33 -> BLN | AL41: ='ISIAN DATA'!H33 -> THN | AM41: ='ISIAN DATA'!I33 -> UMUR
AI42: ='ISIAN DATA'!E34 -> 0 | AJ42: ='ISIAN DATA'!F34 -> 10 | AK42: ='ISIAN DATA'!G34 -> 08 | AL42: ='ISIAN DATA'!H34 -> 2020 | AM42: ='ISIAN DATA'!I34 -> 6
A43: AYAH | AF43: AYAH | AI43: ='ISIAN DATA'!E35 -> 0 | AJ43: ='ISIAN DATA'!F35 -> 0 | AK43: ='ISIAN DATA'!G35 -> 0 | AL43: ='ISIAN DATA'!H35 -> 0 | AM43: ='ISIAN DATA'!I35
A44: 1. | B44: NIK | D44: : | E44: =MID($AI$44,COLUMNS($AI$44:AI44),1) -> 3 | F44: =MID($AI$44,COLUMNS($AI$44:AJ44),1) -> 3 | G44: =MID($AI$44,COLUMNS($AI$44:AK44),1) -> 2 | H44: =MID($AI$44,COLUMNS($AI$44:AL44),1) -> 7 | I44: =MID($AI$44,COLUMNS($AI$44:AM44),1) -> 0 | J44: =MID($AI$44,COLUMNS($AI$44:AN44),1) -> 4 | K44: =MID($AI$44,COLUMNS($AI$44:AO44),1) -> 2 | L44: =MID($AI$44,COLUMNS($AI$44:AP44),1) -> 5 | ... U44: =MID($AI$44,COLUMNS($AI$44:AY44),1) | AF44: 1. | AG44: NIK | AI44: ='ISIAN DATA'!E36 -> 3327042511940003 | AJ44: ='ISIAN DATA'!F36 -> 0 | AK44: ='ISIAN DATA'!G36 -> 0 | AL44: ='ISIAN DATA'!H36 -> 0 | AM44: ='ISIAN DATA'!I36
A45: 2. | B45: Nama Lengkap | D45: : | E45: =MID($AI$45,COLUMNS($AI$45:AI45),1) -> B | F45: =MID($AI$45,COLUMNS($AI$45:AJ45),1) -> U | G45: =MID($AI$45,COLUMNS($AI$45:AK45),1) -> D | H45: =MID($AI$45,COLUMNS($AI$45:AL45),1) -> I | I45: =MID($AI$45,COLUMNS($AI$45:AM45),1) -> A | J45: =MID($AI$45,COLUMNS($AI$45:AN45),1) -> N | K45: =MID($AI$45,COLUMNS($AI$45:AO45),1) -> T | L45: =MID($AI$45,COLUMNS($AI$45:AP45),1) -> O | ... AA45: =MID($AI$45,COLUMNS($AI$45:BE45),1) | AF45: 2. | AG45: Nama Lengkap | AI45: ='ISIAN DATA'!E37 -> BUDIANTO | AJ45: ='ISIAN DATA'!F37 -> 0 | AK45: ='ISIAN DATA'!G37 -> 0 | AL45: ='ISIAN DATA'!H37 -> 0 | AM45: ='ISIAN DATA'!I37
A46: 3. | B46: Tanggal lahir/Umur | D46: : | E46: Tgl | F46: =MID($AJ$47,COLUMNS($AJ$47:AJ47),1) -> 2 | G46: =MID($AJ$47,COLUMNS($AJ$47:AK47),1) -> 5 | I46: Bln. | J46: =MID($AK$47,COLUMNS($AK$47:AK47),1) -> 1 | K46: =MID($AK$47,COLUMNS($AK$47:AL47),1) -> 1 | M46: Thn. | N46: =MID($AL$47,COLUMNS($AL$47:AL47),1) -> 1 | O46: =MID($AL$47,COLUMNS($AL$47:AM47),1) -> 9 | P46: =MID($AL$47,COLUMNS($AL$47:AN47),1) -> 9 | Q46: =MID($AL$47,COLUMNS($AL$47:AO47),1) -> 4 | S46: Umur | U46: =MID($AM$47,COLUMNS($AM$47:AM47),1) -> 3 | V46: =MID($AM$47,COLUMNS($AM$47:AN47),1) -> 2 | AF46: 3. | AG46: Tanggal lahir/Umur | AI46: ='ISIAN DATA'!E38 -> 0 | AJ46: ='ISIAN DATA'!F38 -> TGL | AK46: ='ISIAN DATA'!G38 -> BLN | AL46: ='ISIAN DATA'!H38 -> THN | AM46: ='ISIAN DATA'!I38 -> UMUR
...

Sheet RAB LAPANGAN
B2: RAB
G3: 80000000
D4: Jam
B5: Sewa Alat Berat | C5: 1921000 | D5: 7 | E5: =C5/D5 -> 274428.57 | F5: 28 | G5: =C5*F5 -> 53788000 | H5: =G5*13% -> 6992440
B6: Operator | C6: 250000 | D6: 1 | F6: 28 | G6: =C6*F6 -> 7000000
B7: Dum Truc 2 unit | C7: 452000 | D7: 1 | F7: 26 | G7: =C7*F7 -> 11752000 | H7: =G7*13% -> 1527760
B8: Mob demob | C8: 6000000 | D8: 1 | G8: =C8*D8 -> 6000000 | H8: =G8*13% -> 780000
G11: =SUM(G5:G10) -> 78540000 | H11: =SUM(H5:H10) -> 9300200
B13: RIL | H13: =G3-G11 -> 1460000
D15: Jam
B16: Sewa Alat Berat | C16: 1921000 | D16: 7 | E16: =C16/D16 -> 274428.57 | F16: 28 | G16: =C16*F16 -> 53788000 | H16: =G16*13% -> 6992440
B17: Operator | C17: 250000 | D17: 1 | F17: 28 | G17: =C17*F17 -> 7000000
B18: Dum Truc 2 unit | C18: 452000 | D18: 2 | F18: 28 | G18: =C18*D18*F18 -> 25312000 | H18: =G18*13% -> 3290560
B19: Mob demob | C19: 6000000 | D19: 1 | G19: =C19*D19 -> 6000000 | H19: =G19*13% -> 780000
B20: Mandor | C20: 95000 | F20: 20 | G20: =C20*F20 -> 1900000
B21: Pekerja | C21: 80000 | F21: 28 | G21: =C21*F21 -> 2240000
B22: Bambiu | C22: 1000000 | F22: 1 | G22: =C22*F22 -> 1000000
G27: =SUM(G16:G26) -> 97240000 | H27: =SUM(H16:H26) -> 11063000
B31: SILTAP DES | C31: 23700000 | D31: 1 | F31: =C31*D31 -> 23700000
B32: TUNJANGAN | C32: 2150000 | D32: 1 | F32: =C32*D32 -> 2150000
B34: SIL.KAPEL | C34: 2200000 | D34: 8 | F34: =C34*D34 -> 17600000 | G34: =F34+F35 -> 19360000
B35: TUN.KAPEL | C35: 220000 | D35: 8 | F35: =C35*D35 -> 1760000
B37: TUKIN BPD | C37: 420000 | D37: 1 | F37: =C37*D37 -> 420000
F40: =SUM(F31:F39) -> 45630000
B41: SALDO REK | C41: 61094012 | F41: =C41-F40 -> 15464012
B42: PBJ | F42: 4915000
F43: =F41-F42 -> 10549012
B47: CAMAT | C47: 500000 | D47: 1 | F47: =C47*D47 -> 500000
B48: SEKCAM | C48: 300000 | D48: 1 | F48: =C48*D48 -> 300000
B49: ROM KC | C49: 250000 | D49: 5 | F49: =C49*D49 -> 1250000
B50: PUL | C50: 200000 | D50: 3 | F50: =C50*D50 -> 600000
B51: KOR | C51: 200000 | D51: 3 | F51: =C51*D51 -> 600000
B52: PERANGKAT | C52: 200000 | D52: 10 | F52: =C52*D52 -> 2000000
B53: BPD | C53: 200000 | D53: 5 | F53: =C53*D53 -> 1000000
B54: RT/RW | C54: 50000 | D54: 20 | F54: =C54*D54 -> 1000000
B55: PANITIA | C55: 300000 | D55: 7 | F55: =C55*D55 -> 2100000
B56: LEBAGA | C56: 50000 | D56: 10 | F56: =C56*D56 -> 500000
F57: =C57*D57 -> 0
F58: =C58*D58 -> 0
F59: =C59*D59 -> 0
...

Sheet Sheet5

Sheet Sheet1
B3: SURAT PERNYATAAN BELUM PERNAH MENIKAH
B6: Yang bertanda tangan dibawah ini saya:
B8: Nama lengkap | C8: : | D8: ..............................................................................
B9: Tempat dan Tanggal lahir | C9: : | D9: ..............................................................................
B10: Warganegara | C10: : | D10: ..............................................................................
B11: Agama | C11: : | D11: ..............................................................................
B12: No..NIK | C12: : | D12: ..............................................................................
B13: Pekerjaan | C13: : | D13: ..............................................................................
B14: Alamat | C14: : | D14: ..............................................................................
D15: ..............................................................................
B17: Menyatakan dengan sebenar-benarnya bahwa saya sampai saat ini belum pernah
B18: menikah dengan siapapun baik secara adat hukum Agama,maupun hukum Negara
B19: dan benar--benar masih bersetatus :PERJAKA ( Bujang ).
B21: Demikianlah,surat pernyataan ini saya buat dengan sebenar-benarnya tanpa ada
B22: paksaan dari siapapun,apabila di kemudian hari ternyata pernyataan ini tidak benar,
B23: maka saya siap dituntut sesuai deengan Hukum yang berlaku.
G27: Tambi, ........................................
G29: Yang menyatakan
G33: .............................................
B34: Saksi-saksi
B36: 1........................... | D36: (..........................)
B38: 2........................... | D38: (..........................)
E42: Mengetahui:
E43: Kepala Desa/Lurah Tambi
E48: S O B I Y A H
B74: SURAT PERNYATAAN BELUM PERNAH MENIKAH
B77: Yang bertanda tangan dibawah ini saya:
B79: Nama lengkap | C79: : | D79: DWI JOKO MUARA SABDA
B80: Tempat dan Tanggal lahir | C80: : | D80: Pemalang,28 Agustus 1993
B81: Warganegara | C81: : | D81: Indonesia
B82: Agama | C82: : | D82: Islam
B83: No..NIK | C83: : | D83: 3327042808930000
B84: Pekerjaan | C84: : | D84: POLRI
B85: Alamat | C85: : | D85: Desa Tambi RT.006 RW.001 Kecamatan Watukumpul
D86: Kabupaten Pemalang
B88: Menyatakan dengan sebenar-benarnya bahwa saya sampai saat ini belum pernah
B89: menikah dengan siapapun baik secara adat hukum Agama,maupun hukum Negara
B90: dan benar--benar masih bersetatus :PERJAKA ( Bujang ).
B92: Demikianlah,surat pernyataan ini saya buat dengan sebenar-benarnya tanpa ada
B93: paksaan dari siapapun,apabila di kemudian hari ternyata pernyataan ini tidak benar,
...

Sheet FOM.KK
AZ2: F-1.01
Q3: PEMERINTAH KABUPATEN PEMALANG
Q5: FORMULIR ISIAN BIODATA PENDUDUK UNTUK WNI (PER KELUARGA)
AT8: Diisi Oleh Petugas
B10: DATA KEPALA KELUARGA | AN10: Kode - Nama Provinsi | AR10: : | AT10: 3 | AU10: 3 | AZ10: JAWA TENGAH
B12: Nama Kepala Keluarga | G12: : | AN12: Kode - Nama Kabupaten | AR12: : | AT12: 2 | AU12: 7 | AZ12: PEMALANG
B14: Alamat | G14: : | H14: DESA TAMBI RT 00 RW 00 KECAMATAN WATUKUMPUL | AN14: Kode - Nama Kecamatan | AR14: : | AT14: 4 | AU14: 0 | AZ14: WATUKUMPUL
B16: Kode Pos | G16: : | H16: 5 | I16: 2 | J16: 3 | L16: 5 | M16: 7 | P16: RT | Q16: 0 | X16: RW | Y16: 0 | AC16: Jumlah Anggota Keluarga | AH16: 1 | AI16: 2 | AK16: Orang | AN16: Kode - Nama Desa/Kelurahan | AR16: : | AT16: 0 | AU16: 0 | AW16: 1 | AX16: 1 | AZ16: TAMBI
B18: Telepon | G18: : | AN18: Kode Dusun/Dukuh/Kampung/ | AR18: :
AN19: Lingkungan/Banjar/Nagari
B20: DATA KELUARGA
B22: No | C22: Nama Lengkap | W22: Nomor KTP/Nopen | AD22: Nama Lengkap Ibu | AQ22: NIK Ayah | AY22: Nama Lengkap Ayah
B24: 1 | C24: 2 | W24: 3 | AD24: 4 | AQ24: 5 | AY24: 6
B25: 1 | C25: SARYONO
B26: 2
B27: 3
B28: 4
B29: 5
B30: 6
B31: 7
B32: 8
B33: 9
B34: 10
B36: No | C36: Jenis Kelamin | G36: Tempat Lahir | R36: Tanggal/Bulan/ Tahun Lahir | X36: Umur | Y36: Akta Lahir/ Surat Lahir | AB36: Nomor Akta Kelahiran Surat Kenal Lahir | AD36: Golongan Darah | AG36: Agama | AJ36: Status Perkawinan | AM36: Akta Perkwn/ Buku Nikah*) | AP36: Nomor Akta Perkawinan/ Buku Nikah*) | AS36: Tanggal Perkawinan | AV36: Akta Cerai/ Surat Cerai*) | AY36: Nomor Akta Perceraian/ Surat Cerai*) | BB36: Tanggal Perceraian
C38: 7 | G38: 8 | R38: 9 | X38: 10 | Y38: 11 | AB38: 12 | AD38: 13 | AG38: 14 | AJ38: 15 | AM38: 16 | AP38: 17 | AS38: 18 | AV38: 19 | AY38: 20 | BB38: 21
B39: 1
B40: 2
B41: 3
B42: 4
B43: 5
B44: 6
B45: 7
B46: 8
B47: 9
B48: 10
B50: No | C50: Status Hub. Dlm Keluarga | G50: Kelainan Fisik & Mental | K50: Penyandang Cacat | O50: Pendidikan Terakhir | S50: Pekerjaan | W50: NIK Ibu | AD50: Nama Lengkap Ibu | AQ50: NIK Ayah | AY50: Nama Lengkap Ayah
C52: 22 | G52: 23 | K52: 24 | O52: 25 | S52: 26 | W52: 27 | AD52: 28 | AQ52: 29 | AY52: 30
B53: 1
B54: 2
B55: 3
...

Sheet Sheet2
D3: FORMAT ISIAN DATA
D4: LEMBAGA SOSIIAL KEMASYARAKATAN
D5: Rukun Warga (RW) Dan Rukun Tetangga (RT)
B7: Jumlah RW : 4 (Empat) | D7: Jumlah RT : 16 (Enam belas)
B10: DESA : | C10: TAMBI | D10: KECAMATAN : | E10: WATUKUMPUL
B12: Dengan Rincian Sebagai Berikut:
B14: No.RW | C14: Nama Ketua RW | D14: No.RT | E14: Nama Ketua RT
B16: RW.001 | C16: NUROKIB | D16: RT 001 | E16: DUROJAT
D17: RT 002 | E17: MUNASROH
D18: RT 003 | E18: RASMADI
D19: RT 014 | E19: ALI MUSTAKIM
B22: RW .002 | C22: TURI | D22: RT.010 | E22: MARSONO
D23: RT.011 | E23: SANARDI
D24: RT.012 | E24: RASID | G24: ab
D25: RT.016 | E25: RISWANTO
B28: RW.003 | C28: ROBIL | D28: RT.004 | E28: DIRIN
D29: RT.005 | E29: SUPARJO
D30: RT.006 | E30: SURURI
D31: RT.008 | E31: SURAHMAN
B34: RW.004 | C34: TOHIR | D34: RT.007 | E34: WARSO
D35: RT.009 | E35: SUNARSO
D36: RT.013 | E36: DIRSO
D37: RT.015 | E37: RASMINTO
D42: Tambi,10 Nopember 2017
D44: Kepala Desa Tambi
D48: SOBIYAH

Sheet Sheet3
Z2: KODE.F-2.01
C3: Desa/Kelurahan | F3: : | G3: TAMBI | V3: Ket: | W3: Lembar 1 | Y3: : | Z3: Untuk yang bersangkutan
C4: Kecamatan | F4: : | G4: WATUKUMPUL | W4: Lembar 2 | Y4: : | Z4: Desa/Kelurahan
C5: Pemerintah Kabupaten | F5: : | G5: PEMALANG | W5: Lembar 3 | Y5: : | Z5: Kecamatan
C7: Kode Wilayah | F7: : | G7: 3 | H7: 3 | I7: 2 | J7: 7 | K7: 0 | L7: 4 | M7: 0 | N7: 1 | O7: 1
C10: SURAT KETERANGAN KELAHIRAN
C12: Nama Kepala Keluarga | F12: : | G12: W | H12: A | I12: R | J12: Y | K12: O | L12: N | M12: O
C13: Nomor Kartu Keluarga | F13: : | G13: 3 | H13: 3 | I13: 2 | J13: 7 | K13: 0 | L13: 4 | M13: 2 | N13: 9 | O13: 0 | P13: 9 | Q13: 1 | R13: 6 | S13: 0 | T13: 0 | U13: 0 | V13: 3
C15: BAYI/ANAK
